<?xml version="1.0"?>
<robot name="tricycle_drive" xmlns:xacro="http://ros.org/wiki/xacro">

  <xacro:include filename="$(find antbot_description)/urdf/materials.xacro"/>
  <xacro:include filename="$(find antbot_description)/urdf/sensors/lidar.urdf.xacro"/>

  <xacro:arg name="prefix" default=""/>


  <!-- <xacro:lidar_sensor
    prefix="$(arg prefix)"
    parent="base_link"
    frame_id="laser_frame"
    xyz_offset="0 0 1.0"
    rpy_offset="0 0 0"
    mesh_xyz_offset="0 0 0"
    mesh_rpy_offset="${-M_PI/2} 0 0"
    topic_name="scan"/> -->

  <xacro:lidar_sensor
    prefix="$(arg prefix)"
    parent="base_link"
    frame_id="laser_frame"
    xyz_offset="0 0 1.0"
    rpy_offset="0 0 0"
    mesh_xyz_offset="0 0 0"
    mesh_rpy_offset="0 0 0"
    topic_name="scan"/>

  <link name="base_link" />

  <!-- Chassis -->
  <link name="chassis">
    <collision>
      <origin xyz="0 0 0" rpy="0 0 0" />
      <geometry>
        <box size="1 0.64 0.4" />
      </geometry>
    </collision>

    <visual>
      <origin xyz="0 0 0" rpy="0 0 0" />
      <geometry>
        <box size="1 0.64 0.4" />
      </geometry>
      <material name="Orange" />
    </visual>

    <inertial>
      <origin xyz="0 0 0" rpy="0 0 0" />
      <mass value="10" />
      <inertia ixx="0.126164" ixy="0.0" ixz="0.0" iyy="0.416519" iyz="0.0" izz="0.481014" />
    </inertial>
  </link>

  <joint name="chassis_joint" type="fixed">
    <origin xyz="0.3 0 0.28" rpy="0 0 0" />
    <parent link="base_link" />
    <child link="chassis" />
  </joint>

  <!-- left wheel Link -->
  <link name="left_wheel">
    <collision>
      <geometry>
        <cylinder length="0.08" radius="0.0762" />
      </geometry>
    </collision>
    <visual>
      <geometry>
        <cylinder length="0.08" radius="0.0762" />
      </geometry>
      <material name="Black" />
    </visual>

    <inertial>
      <mass value="5" />
      <inertia ixx="0.145833" ixy="0.0" ixz="0.0" iyy="0.145833" iyz="0.0" izz="0.125" />
    </inertial>
  </link>

  <joint name="left_wheel_joint" type="continuous">
    <origin xyz="-0.3 0.31 -0.2" rpy="-1.57 0 0" />
    <parent link="chassis" />
    <child link="left_wheel" />
    <axis xyz="0 0 1" />
    <dynamics damping="0.5" friction="0.5"/>
  </joint>

  <!-- right wheel Link -->
  <link name="right_wheel">
    <collision>
      <geometry>
        <cylinder length="0.08" radius="0.0762" />
      </geometry>
    </collision>
    <visual>
      <geometry>
        <cylinder length="0.08" radius="0.0762" />
      </geometry>
      <material name="Black" />
    </visual>

    <inertial>
      <mass value="5" />
      <inertia ixx="0.145833" ixy="0.0" ixz="0.0" iyy="0.145833" iyz="0.0" izz="0.125" />
    </inertial>
  </link>

  <joint name="right_wheel_joint" type="continuous">
    <origin xyz="-0.3 -0.31 -0.2" rpy="-1.57 0 0" />
    <parent link="chassis" />
    <child link="right_wheel" />
    <axis xyz="0 0 1" />
    <dynamics damping="0.5" friction="0.5"/>
  </joint>

  <!-- Steering Link -->
  <link name="steering_link">
    <visual>
      <geometry>
        <box size="0.01 0.01 0.01" />
      </geometry>
      <material name="Black" />
    </visual>
    <inertial>
      <origin xyz="0 0 0" rpy="0 0 0" />
      <mass value="0.005" />
      <inertia ixx="0.1" ixy="0.0" ixz="0.0" iyy="0.1" iyz="0.0" izz="0.1" />
    </inertial>
  </link>

  <joint name="steering_joint" type="revolute">
    <origin xyz="0.26 0 -0.18" rpy="0 0 0"/>
    <parent link="chassis"/>
    <child link="steering_link"/>
    <axis xyz="0 0 1"/>
    <limit lower="-0.698" upper="0.698" effort="100" velocity="2.5"/>
    <dynamics damping="0.5" friction="0.0"/>
  </joint>

  <!-- traction wheel link -->
  <link name="wheel_front_link">
    <visual>
      <origin xyz="0 0 0" rpy="0 0 0"/>
      <geometry>
        <cylinder length="0.08" radius="0.1016"/>
      </geometry>
      <material name="Black"/>
    </visual>
    <collision>
      <origin xyz="0 0 0" rpy="0 0 0"/>
      <geometry>
        <cylinder length="0.08" radius="0.1016"/>
      </geometry>
    </collision>
    <inertial>
      <origin xyz="0 0 0" rpy="0 0 0"/>
      <mass value="15"/>
      <inertia ixx="1" ixy="0" ixz="0" iyy="1" iyz="0" izz="1"/>
    </inertial>
  </link>

  <joint name="traction_joint" type="continuous">
    <parent link="steering_link" />
    <child link="wheel_front_link" />
    <origin xyz="0 0 0" rpy="-1.57 1.57 0" />
    <axis xyz="0 0 1" />
  </joint>

  <ros2_control name="GazeboSystem" type="system">
    <hardware>
      <plugin>gz_ros2_control/GazeboSimSystem</plugin>
    </hardware>
    <joint name="steering_joint">
      <command_interface name="position" />
      <state_interface name="position" />
    </joint>
    <joint name="traction_joint">
      <command_interface name="velocity" />
      <state_interface name="velocity" />
      <state_interface name="position" />
    </joint>

    <joint name="left_wheel_joint">
      <state_interface name="position"/>
      <state_interface name="velocity"/>
    </joint>
    <joint name="right_wheel_joint">
      <state_interface name="position"/>
      <state_interface name="velocity"/>
    </joint>    
  </ros2_control>


  <gazebo>
    <plugin filename="gz_ros2_control-system" name="gz_ros2_control::GazeboSimROS2ControlPlugin">
      <parameters>$(find antbot_ros2_control)/config/tricycle_drive_controller.yaml</parameters>
    </plugin>
  </gazebo>

</robot>
