<?xml version="1.0"?>
<robot xmlns:xacro="http://www.ros.org/wiki/xacro">

  <xacro:property name="wheel_radius" value="0.0762" />
  <xacro:property name="wheel_separation" value="0.52" />
  <xacro:property name="wheel_width" value="0.08" />
  <xacro:property name="wheel_mass" value="10.0" />
  <xacro:property name="wheel_xoff" value="0.0" />
  <xacro:property name="wheel_yoff" value="0.0" />
  <xacro:property name="xyz_offset" value="0 0 0" />
  <xacro:property name="rpy_offset" value="0 0 0" />

  <xacro:macro name="rear_wheel" params="prefix side x_reflect y_reflect xyz_offset rpy_offset">
    <link name="${prefix}${side}_wheel_link">
      <visual>
        <origin xyz="${xyz_offset}" rpy="${rpy_offset}"/>
        <geometry>
          <mesh filename="file://$(find antbot_description)/meshes/right_rear_wheel.dae"/>
        </geometry>
      </visual>

      <collision>
        <origin xyz="${xyz_offset}" rpy="${rpy_offset}"/>
        <geometry>
          <mesh filename="file://$(find antbot_description)/meshes/right_rear_wheel.dae"/>
        </geometry>        
      </collision>

      <inertial>
        <origin xyz="0 0 0" rpy="0 0 0"/>
        <mass value="${wheel_mass}"/>
        <inertia
          ixx="${(wheel_mass/12.0) * (3*wheel_radius*wheel_radius + wheel_width*wheel_width)}" ixy="0" ixz="0"
          iyy="${(wheel_mass/2.0) * (wheel_radius*wheel_radius)}" iyz="0"
          izz="${(wheel_mass/12.0) * (3*wheel_radius*wheel_radius + wheel_width*wheel_width)}"/>
      </inertial>
    </link>

    <joint name="${prefix}${side}_wheel_joint" type="continuous">
      <axis xyz="0 1 0"/>
      <parent link="${prefix}base_link"/>
      <child link="${prefix}${side}_wheel_link"/>
      <origin xyz="${x_reflect*wheel_xoff} ${y_reflect*(wheel_separation/2+wheel_yoff)} 0" rpy="0 0 0"/>
    </joint>

    <gazebo reference="${prefix}${side}_wheel_link">
      <surface>
        <friction>
          <ode>
              <mu>1.0</mu>
              <mu2>0.0</mu2>
          </ode>
        </friction>
      </surface>
    </gazebo>

  </xacro:macro>
</robot>